<?xml version="1.0"?>
<robot xmlns:xacro="http://ros.org/wiki/xacro">

  <xacro:property name="wheel_radius" value="0.1"/>
  <xacro:property name="wheel_length" value="0.04"/>
  <xacro:property name="wheel_mass" value="0.2"/>

  <xacro:macro name="wheel_link" params="side x y">
    <link name="${side}_wheel">
      <visual>
        <origin rpy="0 1.5707 1.5707" xyz="0 0 0"/>
        <geometry><cylinder length="${wheel_length}" radius="${wheel_radius}"/></geometry>
        <material name="blue"><color rgba="0.2 0.2 1.0 1.0"/></material>
      </visual>
      <inertial>
        <mass value="${wheel_mass}"/>
        <origin rpy="0 1.5707 1.5707" xyz="0 0 0"/>
        <inertia ixx="0.00052666666" ixy="0" ixz="0"
                 iyy="0.00052666666" iyz="0" izz="0.001"/>
      </inertial>
      <collision>
        <origin rpy="0 1.5707 1.5707" xyz="0 0 0"/>
        <geometry><cylinder length="${wheel_length}" radius="${wheel_radius}"/></geometry>
      </collision>
    </link>

    <joint name="${side}_wheel_hinge" type="continuous">
      <origin rpy="0 0 0" xyz="${x} ${y} 0"/>
      <child link="${side}_wheel"/>
      <parent link="base_link_chassis"/>
      <axis xyz="0 1 0"/>
      <limit effort="10000" velocity="1000"/>
      <joint_properties damping="1.0" friction="1.0"/>
    </joint>
  </xacro:macro>

  <xacro:wheel_link side="right" x="-0.05" y="0.15"/>
  <xacro:wheel_link side="left"  x="-0.05" y="-0.15"/>

</robot>